{"trial_id": "0001", "hyperparameters": {"space": [{"class_name": "Choice", "config": {"name": "num_layers", "default": 1, "conditions": [], "values": [1, 2, 3], "ordered": true}}, {"class_name": "Int", "config": {"name": "dense_units", "default": null, "conditions": [], "min_value": 16, "max_value": 256, "step": 16, "sampling": "linear"}}, {"class_name": "Float", "config": {"name": "dropout_rate", "default": 0.1, "conditions": [], "min_value": 0.1, "max_value": 0.8, "step": 0.1, "sampling": "linear"}}, {"class_name": "Choice", "config": {"name": "learning_rate", "default": 0.01, "conditions": [], "values": [0.01, 0.001, 0.0001], "ordered": true}}], "values": {"num_layers": 2, "dense_units": 208, "dropout_rate": 0.6, "learning_rate": 0.0001, "tuner/epochs": 2, "tuner/initial_epoch": 0, "tuner/bracket": 2, "tuner/round": 0}}, "metrics": {"metrics": {}}, "score": null, "best_step": 0, "status": "FAILED", "message": "Traceback (most recent call last):\n  File \"D:\\AI-ML_Project\\machine-learning-operations-mlops\\submissions\\submission-1\\.venv\\lib\\site-packages\\keras_tuner\\src\\engine\\base_tuner.py\", line 273, in _try_run_and_update_trial\n    self._run_and_update_trial(trial, *fit_args, **fit_kwargs)\n  File \"D:\\AI-ML_Project\\machine-learning-operations-mlops\\submissions\\submission-1\\.venv\\lib\\site-packages\\keras_tuner\\src\\engine\\base_tuner.py\", line 238, in _run_and_update_trial\n    results = self.run_trial(trial, *fit_args, **fit_kwargs)\n  File \"D:\\AI-ML_Project\\machine-learning-operations-mlops\\submissions\\submission-1\\.venv\\lib\\site-packages\\keras_tuner\\src\\tuners\\hyperband.py\", line 427, in run_trial\n    return super().run_trial(trial, *fit_args, **fit_kwargs)\n  File \"D:\\AI-ML_Project\\machine-learning-operations-mlops\\submissions\\submission-1\\.venv\\lib\\site-packages\\keras_tuner\\src\\engine\\tuner.py\", line 314, in run_trial\n    obj_value = self._build_and_fit_model(trial, *args, **copied_kwargs)\n  File \"D:\\AI-ML_Project\\machine-learning-operations-mlops\\submissions\\submission-1\\.venv\\lib\\site-packages\\keras_tuner\\src\\engine\\tuner.py\", line 233, in _build_and_fit_model\n    results = self.hypermodel.fit(hp, model, *args, **kwargs)\n  File \"D:\\AI-ML_Project\\machine-learning-operations-mlops\\submissions\\submission-1\\.venv\\lib\\site-packages\\keras_tuner\\src\\engine\\hypermodel.py\", line 149, in fit\n    return model.fit(*args, **kwargs)\n  File \"D:\\AI-ML_Project\\machine-learning-operations-mlops\\submissions\\submission-1\\.venv\\lib\\site-packages\\keras\\src\\utils\\traceback_utils.py\", line 70, in error_handler\n    raise e.with_traceback(filtered_tb) from None\n  File \"C:\\Users\\Asus\\AppData\\Local\\Temp\\__autograph_generated_fileun4latkj.py\", line 15, in tf__train_function\n    retval_ = ag__.converted_call(ag__.ld(step_function), (ag__.ld(self), ag__.ld(iterator)), None, fscope)\nValueError: in user code:\n\n    File \"D:\\AI-ML_Project\\machine-learning-operations-mlops\\submissions\\submission-1\\.venv\\lib\\site-packages\\keras\\src\\engine\\training.py\", line 1338, in train_function  *\n        return step_function(self, iterator)\n    File \"D:\\AI-ML_Project\\machine-learning-operations-mlops\\submissions\\submission-1\\.venv\\lib\\site-packages\\keras\\src\\engine\\training.py\", line 1322, in step_function  **\n        outputs = model.distribute_strategy.run(run_step, args=(data,))\n    File \"D:\\AI-ML_Project\\machine-learning-operations-mlops\\submissions\\submission-1\\.venv\\lib\\site-packages\\keras\\src\\engine\\training.py\", line 1303, in run_step  **\n        outputs = model.train_step(data)\n    File \"D:\\AI-ML_Project\\machine-learning-operations-mlops\\submissions\\submission-1\\.venv\\lib\\site-packages\\keras\\src\\engine\\training.py\", line 1080, in train_step\n        y_pred = self(x, training=True)\n    File \"D:\\AI-ML_Project\\machine-learning-operations-mlops\\submissions\\submission-1\\.venv\\lib\\site-packages\\keras\\src\\utils\\traceback_utils.py\", line 70, in error_handler\n        raise e.with_traceback(filtered_tb) from None\n    File \"D:\\AI-ML_Project\\machine-learning-operations-mlops\\submissions\\submission-1\\.venv\\lib\\site-packages\\keras\\src\\engine\\input_spec.py\", line 197, in assert_input_compatibility\n        raise ValueError(\n\n    ValueError: Missing data for input \"input_1\". You passed a data dictionary with keys ['review_xf']. Expected the following keys: ['input_1']\n\n"}